File: example_data/manufacturers/netzsch_example3.txt
#EXPORTTYPE:DATA ALL
#FILE:CF-A_1000-ash.ngb-ds3
#FORMAT:NETZSCH5
#FTYPE:ASCII
#IDENTITY:CF-A_1000-ash
#DECIMAL:POINT
#SEPARATOR:SEMICOLON
#MTYPE:TG
#INSTRUMENT:NETZSCH STA 449F3
#PROJECT:
#DATE/TIME:08.10.2024 15:04
#CORR. FILE:blanc_1000_air.ngb-bs3
#TEMPCAL:TCALZERO.TCX
#SENSITIVITY:---
#LABORATORY:IJL
#OPERATOR:TS
#REMARK:
#SAMPLE:CF-A_1000-ash
#SAMPLE MASS /mg:4.28
#MATERIAL:
#REFERENCE:
#REFERENCE MASS /mg:
#TYPE OF CRUCIBLE:DTA/TG crucible Al2O3
#SAMPLE CRUCIBLE MASS /mg:0
#REFERENCE CRUCIBLE MASS /mg:
#TG RANGE /mg:35000
#TAU-R:---
#CORR. CODE:020
#EXO:-1
#RANGE:37›C/15,0(K/min)/1000›C/00:00/1000›C/
#SEGMENT:S1-2/2
#SEG. 1:37›C/15,0(K/min)/1000›C
#SEG. 2:1000›C/00:30/1000›C

##Temp./›C;Time/min;Mass/%;Gas Flow(purge2)/(ml/min);Gas Flow(protective)/(ml/min);Segment
  31.06100; 0.00000;100.00000;50.00000;40.00000;1
  31.06000; 0.08000; 99.95327;50.00000;40.00000;1
  31.05300; 0.16000; 99.95327;50.00000;40.00000;1
  31.06800; 0.24000;100.00000;50.00000;40.00000;1
  31.11000; 0.32000;100.02336;50.00000;40.00000;1
  31.19600; 0.40000;100.09346;50.00000;40.00000;1
  31.33600; 0.48000;100.28037;50.00000;40.00000;1
  31.51900; 0.56000;100.44393;50.00000;40.00000;1
  31.75100; 0.64000;100.65421;50.00000;40.00000;1
  32.04700; 0.72000;100.77103;50.00000;40.00000;1
  32.37100; 0.80000;100.91122;50.00000;40.00000;1
  32.75000; 0.88000;101.02804;50.00000;40.00000;1
  33.17800; 0.96000;101.09813;50.00000;40.00000;1
  33.60600; 1.04000;101.16822;50.00000;40.00000;1
  34.09300; 1.12000;101.26168;50.00000;40.00000;1
  34.61300; 1.20000;101.37850;50.00000;40.00000;1
  35.18900; 1.28000;101.47196;50.00000;40.00000;1
  35.79700; 1.36000;101.56542;50.00000;40.00000;1
  36.41200; 1.44000;101.63551;50.00000;40.00000;1
  37.08200; 1.52000;101.63551;50.00000;40.00000;1
  37.80500; 1.60000;101.70561;50.00000;40.00000;1
  38.53700; 1.68000;101.75234;50.00000;40.00000;1
  39.32500; 1.76000;101.75234;50.00000;40.00000;1
  40.14300; 1.84000;101.79907;50.00000;40.00000;1
  40.98400; 1.92000;101.77570;50.00000;40.00000;1
  41.87400; 2.00000;101.75234;50.00000;40.00000;1
  42.78100; 2.08000;101.77570;50.00000;40.00000;1
  43.72300; 2.16000;101.84579;50.00000;40.00000;1
  44.70900; 2.24000;101.77570;50.00000;40.00000;1
  45.70100; 2.32000;101.77570;50.00000;40.00000;1
  46.74400; 2.40000;101.75234;50.00000;40.00000;1
  47.79000; 2.48000;101.72897;50.00000;40.00000;1
  48.87100; 2.56000;101.75234;50.00000;40.00000;1
  49.96400; 2.64000;101.79907;50.00000;40.00000;1
  51.11800; 2.72000;101.79907;50.00000;40.00000;1
  52.26100; 2.80000;101.77570;50.00000;40.00000;1
  53.44600; 2.88000;101.77570;50.00000;40.00000;1
  54.64500; 2.96000;101.77570;50.00000;40.00000;1
  55.86500; 3.04000;101.77570;50.00000;40.00000;1
  57.09900; 3.12000;101.77570;50.00000;40.00000;1
  58.35800; 3.20000;101.79907;50.00000;40.00000;1
  59.61900; 3.28000;101.75234;50.00000;40.00000;1
  60.91200; 3.36000;101.72897;50.00000;40.00000;1
  62.22600; 3.44000;101.70561;50.00000;40.00000;1
  63.55400; 3.52000;101.68224;50.00000;40.00000;1
  64.90300; 3.60000;101.65888;50.00000;40.00000;1
  66.26200; 3.68000;101.65888;50.00000;40.00000;1
  67.61700; 3.76000;101.61215;50.00000;40.00000;1
  68.99900; 3.84000;101.65888;50.00000;40.00000;1
  70.38700; 3.92000;101.68224;50.00000;40.00000;1
  71.78800; 4.00000;101.63551;50.00000;40.00000;1
  73.21100; 4.08000;101.68224;50.00000;40.00000;1
  74.63700; 4.16000;101.65888;50.00000;40.00000;1
  76.06300; 4.24000;101.63551;50.00000;40.00000;1
  77.50000; 4.32000;101.61215;50.00000;40.00000;1
  78.96000; 4.40000;101.58879;50.00000;40.00000;1
  80.41700; 4.48000;101.58878;50.00000;40.00000;1
  81.87600; 4.56000;101.54206;50.00000;40.00000;1
  83.35900; 4.64000;101.54206;50.00000;40.00000;1
  84.84200; 4.72000;101.51869;50.00000;40.00000;1
  86.32700; 4.80000;101.51869;50.00000;40.00000;1
  87.83500; 4.88000;101.51869;50.00000;40.00000;1
  89.33100; 4.96000;101.44860;50.00000;40.00000;1
  90.84800; 5.04000;101.44860;50.00000;40.00000;1
  92.35900; 5.12000;101.42523;50.00000;40.00000;1
  93.89700; 5.20000;101.42523;50.00000;40.00000;1
  95.42800; 5.28000;101.37850;50.00000;40.00000;1
  96.94000; 5.36000;101.33178;50.00000;40.00000;1
  98.48500; 5.44000;101.35514;50.00000;40.00000;1
 100.01700; 5.52000;101.33178;50.00000;40.00000;1
 101.54300; 5.60000;101.33178;50.00000;40.00000;1
 103.08000; 5.68000;101.37850;50.00000;40.00000;1
 104.59900; 5.76000;101.33178;50.00000;40.00000;1
 106.13300; 5.84000;101.26168;50.00000;40.00000;1
 107.66200; 5.92000;101.23832;50.00000;40.00000;1
 109.18400; 6.00000;101.26168;50.00000;40.00000;1
 110.71600; 6.08000;101.26168;50.00000;40.00000;1
 112.25300; 6.16000;101.26168;50.00000;40.00000;1
 113.75200; 6.24000;101.23832;50.00000;40.00000;1
 115.29000; 6.32000;101.21495;50.00000;40.00000;1
 116.81500; 6.40000;101.21495;50.00000;40.00000;1
 118.33900; 6.48000;101.23832;50.00000;40.00000;1
 119.86900; 6.56000;101.23832;50.00000;40.00000;1
 121.38900; 6.64000;101.26168;50.00000;40.00000;1
 122.91000; 6.72000;101.26168;50.00000;40.00000;1
 124.43500; 6.80000;101.26168;50.00000;40.00000;1
 125.96100; 6.88000;101.23832;50.00000;40.00000;1
 127.47900; 6.96000;101.23832;50.00000;40.00000;1
 129.01100; 7.04000;101.23832;50.00000;40.00000;1
 130.52499; 7.12000;101.23832;50.00000;40.00000;1
 132.04300; 7.20000;101.28505;50.00000;40.00000;1
 133.56400; 7.28000;101.28505;50.00000;40.00000;1
 135.08200; 7.36000;101.28505;50.00000;40.00000;1
 136.59200; 7.44000;101.28505;50.00000;40.00000;1
 138.08501; 7.52000;101.28505;50.00000;40.00000;1
 139.60300; 7.60000;101.28505;50.00000;40.00000;1
 141.10300; 7.68000;101.28505;50.00000;40.00000;1
 142.62000; 7.76000;101.28505;50.00000;40.00000;1
 144.10300; 7.84000;101.28505;50.00000;40.00000;1
 145.59500; 7.92000;101.28505;50.00000;40.00000;1
 147.09200; 8.00000;101.28505;50.00000;40.00000;1
 148.57100; 8.08000;101.28505;50.00000;40.00000;1
 150.06000; 8.16000;101.28505;50.00000;40.00000;1
 151.55099; 8.24000;101.28505;50.00000;40.00000;1
 153.01401; 8.32000;101.28505;50.00000;40.00000;1
 154.48599; 8.40000;101.28505;50.00000;40.00000;1
 155.96700; 8.48000;101.28505;50.00000;40.00000;1
 157.41701; 8.56000;101.28505;50.00000;40.00000;1
 158.88100; 8.64000;101.28505;50.00000;40.00000;1
 160.32899; 8.72000;101.28505;50.00000;40.00000;1
 161.77100; 8.80000;101.28505;50.00000;40.00000;1
 163.20799; 8.88000;101.28505;50.00000;40.00000;1
 164.65401; 8.96000;101.33178;50.00000;40.00000;1
 166.07800; 9.04000;101.33178;50.00000;40.00000;1
 167.50000; 9.12000;101.33178;50.00000;40.00000;1
 168.91400; 9.20000;101.33178;50.00000;40.00000;1
 170.33299; 9.28000;101.33178;50.00000;40.00000;1
 171.75101; 9.36000;101.33178;50.00000;40.00000;1
 173.15900; 9.44000;101.33178;50.00000;40.00000;1
 174.53600; 9.52000;101.33178;50.00000;40.00000;1
 175.94701; 9.60000;101.37850;50.00000;40.00000;1
 177.33600; 9.68000;101.37850;50.00000;40.00000;1
 178.72600; 9.76000;101.37850;50.00000;40.00000;1
 180.10500; 9.84000;101.37850;50.00000;40.00000;1
 181.50500; 9.92000;101.42523;50.00000;40.00000;1
 182.85699;10.00000;101.42523;50.00000;40.00000;1
 184.23801;10.08000;101.42523;50.00000;40.00000;1
 185.61099;10.16000;101.42523;50.00000;40.00000;1
 186.98000;10.24000;101.42523;50.00000;40.00000;1
 188.34000;10.32000;101.51869;50.00000;40.00000;1
 189.69800;10.40000;101.51869;50.00000;40.00000;1
 191.04800;10.48000;101.51869;50.00000;40.00000;1
 192.40800;10.56000;101.51869;50.00000;40.00000;1
 193.75200;10.64000;101.51869;50.00000;40.00000;1
 195.08900;10.72000;101.49533;50.00000;40.00000;1
 196.42400;10.80000;101.49533;50.00000;40.00000;1
 197.76700;10.88000;101.49533;50.00000;40.00000;1
 199.09801;10.96000;101.49533;50.00000;40.00000;1
 200.43100;11.04000;101.49533;50.00000;40.00000;1
 201.75400;11.12000;101.49533;50.00000;40.00000;1
 203.08701;11.20000;101.51869;50.00000;40.00000;1
 204.40300;11.28000;101.51869;50.00000;40.00000;1
 205.72400;11.36000;101.54206;50.00000;40.00000;1
 207.03500;11.44000;101.56542;50.00000;40.00000;1
 208.33099;11.52000;101.58878;50.00000;40.00000;1
 209.64900;11.60000;101.61215;50.00000;40.00000;1
 210.93800;11.68000;101.61215;50.00000;40.00000;1
 212.24300;11.76000;101.68224;50.00000;40.00000;1
 213.53200;11.84000;101.68224;50.00000;40.00000;1
 214.81200;11.92000;101.68224;50.00000;40.00000;1
 216.11200;12.00000;101.70561;50.00000;40.00000;1
 217.38000;12.08000;101.72897;50.00000;40.00000;1
 218.66400;12.16000;101.72897;50.00000;40.00000;1
 219.92799;12.24000;101.72897;50.00000;40.00000;1
 221.20200;12.32000;101.72897;50.00000;40.00000;1
 222.48199;12.40000;101.72897;50.00000;40.00000;1
 223.74699;12.48000;101.75234;50.00000;40.00000;1
 224.99699;12.56000;101.75234;50.00000;40.00000;1
 226.25101;12.64000;101.75234;50.00000;40.00000;1
 227.51601;12.72000;101.75234;50.00000;40.00000;1
 228.77400;12.80000;101.75234;50.00000;40.00000;1
 230.01401;12.88000;101.75234;50.00000;40.00000;1
 231.27400;12.96000;101.77570;50.00000;40.00000;1
 232.52200;13.04000;101.77570;50.00000;40.00000;1
 233.76900;13.12000;101.77570;50.00000;40.00000;1
 235.00800;13.20000;101.77570;50.00000;40.00000;1
 236.24899;13.28000;101.77570;50.00000;40.00000;1
 237.48700;13.36000;101.79907;50.00000;40.00000;1
 238.74200;13.44000;101.79907;50.00000;40.00000;1
 239.97701;13.52000;101.79907;50.00000;40.00000;1
 241.21700;13.60000;101.79907;50.00000;40.00000;1
 242.45000;13.68000;101.79907;50.00000;40.00000;1
 243.68500;13.76000;101.79907;50.00000;40.00000;1
 244.90900;13.84000;101.82243;50.00000;40.00000;1
 246.14799;13.92000;101.82243;50.00000;40.00000;1
 247.37601;14.00000;101.82243;50.00000;40.00000;1
 248.59399;14.08000;101.82243;50.00000;40.00000;1
 249.82800;14.16000;101.86916;50.00000;40.00000;1
 251.06700;14.24000;101.86916;50.00000;40.00000;1
 252.27200;14.32000;101.86916;50.00000;40.00000;1
 253.49699;14.40000;101.91589;50.00000;40.00000;1
 254.71001;14.48000;101.91589;50.00000;40.00000;1
 255.92700;14.56000;101.91589;50.00000;40.00000;1
 257.14401;14.64000;101.91589;50.00000;40.00000;1
 258.36600;14.72000;101.98598;50.00000;40.00000;1
 259.58099;14.80000;101.98598;50.00000;40.00000;1
 260.79199;14.88000;101.98598;50.00000;40.00000;1
 262.00000;14.96000;102.00935;50.00000;40.00000;1
 263.21600;15.04000;102.00935;50.00000;40.00000;1
 264.42499;15.12000;102.00935;50.00000;40.00000;1
 265.63901;15.20000;102.05607;50.00000;40.00000;1
 266.84900;15.28000;102.05607;50.00000;40.00000;1
 268.05801;15.36000;102.05607;50.00000;40.00000;1
 269.26801;15.44000;102.10280;50.00000;40.00000;1
 270.47501;15.52000;102.10280;50.00000;40.00000;1
 271.68900;15.60000;102.10280;50.00000;40.00000;1
 272.88101;15.68000;102.10280;50.00000;40.00000;1
 274.08499;15.76000;102.14953;50.00000;40.00000;1
 275.29901;15.84000;102.14953;50.00000;40.00000;1
 276.50000;15.92000;102.14953;50.00000;40.00000;1
 277.70599;16.00000;102.19626;50.00000;40.00000;1
 278.91901;16.08000;102.21963;50.00000;40.00000;1
 280.11099;16.16000;102.24299;50.00000;40.00000;1
 281.31601;16.24000;102.24299;50.00000;40.00000;1
 282.50699;16.32000;102.26636;50.00000;40.00000;1
 283.71500;16.40000;102.28972;50.00000;40.00000;1
 284.92300;16.48000;102.31308;50.00000;40.00000;1
 286.11401;16.56000;102.31308;50.00000;40.00000;1
 287.29800;16.64000;102.33645;50.00000;40.00000;1
 288.50800;16.72000;102.35981;50.00000;40.00000;1
 289.70999;16.80000;102.35981;50.00000;40.00000;1
 290.90100;16.88000;102.35981;50.00000;40.00000;1
 292.09900;16.96000;102.38318;50.00000;40.00000;1
 293.28799;17.04000;102.38318;50.00000;40.00000;1
 294.48801;17.12000;102.38318;50.00000;40.00000;1
 295.69299;17.20000;102.38318;50.00000;40.00000;1
 296.88101;17.28000;102.38318;50.00000;40.00000;1
 298.08600;17.36000;102.40654;50.00000;40.00000;1
 299.27600;17.44000;102.40654;50.00000;40.00000;1
 300.46201;17.52000;102.38318;50.00000;40.00000;1
 301.66101;17.60000;102.38318;50.00000;40.00000;1
 302.85501;17.68000;102.38318;50.00000;40.00000;1
 304.04599;17.76000;102.38318;50.00000;40.00000;1
 305.23499;17.84000;102.38318;50.00000;40.00000;1
 306.43201;17.92000;102.38318;50.00000;40.00000;1
 307.62399;18.00000;102.38318;50.00000;40.00000;1
 308.81500;18.08000;102.38318;50.00000;40.00000;1
 309.99701;18.16000;102.38318;50.00000;40.00000;1
 311.19601;18.24000;102.38318;50.00000;40.00000;1
 312.38199;18.32000;102.38318;50.00000;40.00000;1
 313.58499;18.40000;102.40654;50.00000;40.00000;1
 314.76599;18.48000;102.42991;50.00000;40.00000;1
 315.96201;18.56000;102.45327;50.00000;40.00000;1
 317.14301;18.64000;102.50000;50.00000;40.00000;1
 318.32901;18.72000;102.52336;50.00000;40.00000;1
 319.52399;18.80000;102.52336;50.00000;40.00000;1
 320.71600;18.88000;102.52336;50.00000;40.00000;1
 321.90601;18.96000;102.52336;50.00000;40.00000;1
 323.09601;19.04000;102.52336;50.00000;40.00000;1
 324.28799;19.12000;102.52336;50.00000;40.00000;1
 325.48700;19.20000;102.54673;50.00000;40.00000;1
 326.67099;19.28000;102.54673;50.00000;40.00000;1
 327.86200;19.36000;102.54673;50.00000;40.00000;1
 329.05600;19.44000;102.54673;50.00000;40.00000;1
 330.24100;19.52000;102.52336;50.00000;40.00000;1
 331.43100;19.60000;102.52336;50.00000;40.00000;1
 332.62799;19.68000;102.52336;50.00000;40.00000;1
 333.82101;19.76000;102.50000;50.00000;40.00000;1
 335.01501;19.84000;102.50000;50.00000;40.00000;1
 336.20300;19.92000;102.47664;50.00000;40.00000;1
 337.40500;20.00000;102.52336;50.00000;40.00000;1
 338.59799;20.08000;102.52336;50.00000;40.00000;1
 339.79300;20.16000;102.52336;50.00000;40.00000;1
 340.98099;20.24000;102.52336;50.00000;40.00000;1
 342.17300;20.32000;102.52336;50.00000;40.00000;1
 343.35400;20.40000;102.52336;50.00000;40.00000;1
 344.54599;20.48000;102.52336;50.00000;40.00000;1
 345.74200;20.56000;102.52336;50.00000;40.00000;1
 346.92999;20.64000;102.52336;50.00000;40.00000;1
 348.12701;20.72000;102.52336;50.00000;40.00000;1
 349.31799;20.80000;102.52336;50.00000;40.00000;1
 350.50201;20.88000;102.50000;50.00000;40.00000;1
 351.68701;20.96000;102.50000;50.00000;40.00000;1
 352.88599;21.04000;102.47664;50.00000;40.00000;1
 354.08099;21.12000;102.47664;50.00000;40.00000;1
 355.25800;21.20000;102.47664;50.00000;40.00000;1
 356.45001;21.28000;102.47664;50.00000;40.00000;1
 357.63901;21.36000;102.52336;50.00000;40.00000;1
 358.83801;21.44000;102.52336;50.00000;40.00000;1
 360.02600;21.52000;102.52336;50.00000;40.00000;1
 361.21201;21.60000;102.52336;50.00000;40.00000;1
 362.41101;21.68000;102.52336;50.00000;40.00000;1
 363.59201;21.76000;102.57009;50.00000;40.00000;1
 364.77600;21.84000;102.57009;50.00000;40.00000;1
 365.96899;21.92000;102.61682;50.00000;40.00000;1
 367.15500;22.00000;102.61682;50.00000;40.00000;1
 368.34698;22.08000;102.61682;50.00000;40.00000;1
 369.53299;22.16000;102.66355;50.00000;40.00000;1
 370.73001;22.24000;102.64019;50.00000;40.00000;1
 371.90799;22.32000;102.61682;50.00000;40.00000;1
 373.10699;22.40000;102.59346;50.00000;40.00000;1
 374.29599;22.48000;102.57009;50.00000;40.00000;1
 375.48700;22.56000;102.57009;50.00000;40.00000;1
 376.67099;22.64000;102.57009;50.00000;40.00000;1
 377.86301;22.72000;102.57009;50.00000;40.00000;1
 379.04401;22.80000;102.54673;50.00000;40.00000;1
 380.22900;22.88000;102.54673;50.00000;40.00000;1
 381.42001;22.96000;102.54673;50.00000;40.00000;1
 382.61700;23.04000;102.52336;50.00000;40.00000;1
 383.80200;23.12000;102.52336;50.00000;40.00000;1
 384.99200;23.20000;102.52336;50.00000;40.00000;1
 386.17300;23.28000;102.52336;50.00000;40.00000;1
 387.37000;23.36000;102.57009;50.00000;40.00000;1
 388.56000;23.44000;102.61682;50.00000;40.00000;1
 389.75101;23.52000;102.61682;50.00000;40.00000;1
 390.93600;23.60000;102.61682;50.00000;40.00000;1
 392.13199;23.68000;102.59346;50.00000;40.00000;1
 393.31500;23.76000;102.57009;50.00000;40.00000;1
 394.50101;23.84000;102.57009;50.00000;40.00000;1
 395.69101;23.92000;102.57009;50.00000;40.00000;1
 396.88800;24.00000;102.57009;50.00000;40.00000;1
 398.07599;24.08000;102.54673;50.00000;40.00000;1
 399.26901;24.16000;102.54673;50.00000;40.00000;1
 400.46201;24.24000;102.52336;50.00000;40.00000;1
 401.64401;24.32000;102.52336;50.00000;40.00000;1
 402.85101;24.40000;102.52336;50.00000;40.00000;1
 404.03201;24.48000;102.52336;50.00000;40.00000;1
 405.23001;24.56000;102.52336;50.00000;40.00000;1
 406.42300;24.64000;102.52336;50.00000;40.00000;1
 407.61700;24.72000;102.52336;50.00000;40.00000;1
 408.80399;24.80000;102.52336;50.00000;40.00000;1
 410.01001;24.88000;102.52336;50.00000;40.00000;1
 411.19400;24.96000;102.52336;50.00000;40.00000;1
 412.39700;25.04000;102.52336;50.00000;40.00000;1
 413.58600;25.12000;102.50000;50.00000;40.00000;1
 414.77701;25.20000;102.50000;50.00000;40.00000;1
 415.97601;25.28000;102.47664;50.00000;40.00000;1
 417.15500;25.36000;102.45327;50.00000;40.00000;1
 418.36099;25.44000;102.45327;50.00000;40.00000;1
 419.54800;25.52000;102.38318;50.00000;40.00000;1
 420.74500;25.60000;102.38318;50.00000;40.00000;1
 421.93500;25.68000;102.38318;50.00000;40.00000;1
 423.13199;25.76000;102.38318;50.00000;40.00000;1
 424.33099;25.84000;102.38318;50.00000;40.00000;1
 425.51599;25.92000;102.38318;50.00000;40.00000;1
 426.70599;26.00000;102.38318;50.00000;40.00000;1
 427.90100;26.08000;102.42991;50.00000;40.00000;1
 429.09900;26.16000;102.38318;50.00000;40.00000;1
 430.28400;26.24000;102.42991;50.00000;40.00000;1
 431.48199;26.32000;102.42991;50.00000;40.00000;1
 432.67200;26.40000;102.42991;50.00000;40.00000;1
 433.86801;26.48000;102.47663;50.00000;40.00000;1
 435.06201;26.56000;102.50000;50.00000;40.00000;1
 436.24500;26.64000;102.45327;50.00000;40.00000;1
 437.43100;26.72000;102.47664;50.00000;40.00000;1
 438.63300;26.80000;102.47664;50.00000;40.00000;1
 439.82901;26.88000;102.50000;50.00000;40.00000;1
 441.00800;26.96000;102.50000;50.00000;40.00000;1
 442.21100;27.04000;102.52336;50.00000;40.00000;1
 443.40100;27.12000;102.52336;50.00000;40.00000;1
 444.60101;27.20000;102.52336;50.00000;40.00000;1
 445.79501;27.28000;102.54673;50.00000;40.00000;1
 446.99301;27.36000;102.54673;50.00000;40.00000;1
 448.17801;27.44000;102.57009;50.00000;40.00000;1
 449.37399;27.52000;102.57009;50.00000;40.00000;1
 450.57001;27.60000;102.57009;50.00000;40.00000;1
 451.76300;27.68000;102.54673;50.00000;40.00000;1
 452.95901;27.76000;102.54673;50.00000;40.00000;1
 454.14999;27.84000;102.54673;50.00000;40.00000;1
 455.34201;27.92000;102.54673;50.00000;40.00000;1
 456.52499;28.00000;102.54673;50.00000;40.00000;1
 457.73099;28.08000;102.50000;50.00000;40.00000;1
 458.92401;28.16000;102.50000;50.00000;40.00000;1
 460.10999;28.24000;102.50000;50.00000;40.00000;1
 461.31100;28.32000;102.50000;50.00000;40.00000;1
 462.49899;28.40000;102.50000;50.00000;40.00000;1
 463.69101;28.48000;102.45327;50.00000;40.00000;1
 464.89099;28.56000;102.45327;50.00000;40.00000;1
 466.08701;28.64000;102.45327;50.00000;40.00000;1
 467.27899;28.72000;102.45327;50.00000;40.00000;1
 468.46100;28.80000;102.45327;50.00000;40.00000;1
 469.67099;28.88000;102.45327;50.00000;40.00000;1
 470.85901;28.96000;102.40654;50.00000;40.00000;1
 472.05200;29.04000;102.40654;50.00000;40.00000;1
 473.26599;29.12000;102.40654;50.00000;40.00000;1
 474.45099;29.20000;102.38318;50.00000;40.00000;1
 475.65500;29.28000;102.38318;50.00000;40.00000;1
 476.85199;29.36000;102.38318;50.00000;40.00000;1
 478.04300;29.44000;102.38318;50.00000;40.00000;1
 479.25699;29.52000;102.38318;50.00000;40.00000;1
 480.45099;29.60000;102.35981;50.00000;40.00000;1
 481.65701;29.68000;102.33645;50.00000;40.00000;1
 482.85501;29.76000;102.35981;50.00000;40.00000;1
 484.05301;29.84000;102.35981;50.00000;40.00000;1
 485.24301;29.92000;102.35981;50.00000;40.00000;1
 486.44000;30.00000;102.35981;50.00000;40.00000;1
 487.62799;30.08000;102.33645;50.00000;40.00000;1
 488.81699;30.16000;102.33645;50.00000;40.00000;1
 490.00900;30.24000;102.35981;50.00000;40.00000;1
 491.20099;30.32000;102.35981;50.00000;40.00000;1
 492.39700;30.40000;102.38318;50.00000;40.00000;1
 493.59500;30.48000;102.38318;50.00000;40.00000;1
 494.77899;30.56000;102.40654;50.00000;40.00000;1
 495.97400;30.64000;102.38318;50.00000;40.00000;1
 497.17401;30.72000;102.38318;50.00000;40.00000;1
 498.35800;30.80000;102.40654;50.00000;40.00000;1
 499.56400;30.88000;102.38318;50.00000;40.00000;1
 500.73901;30.96000;102.38318;50.00000;40.00000;1
 501.94601;31.04000;102.35981;50.00000;40.00000;1
 503.13400;31.12000;102.35981;50.00000;40.00000;1
 504.32901;31.20000;102.35981;50.00000;40.00000;1
 505.52399;31.28000;102.35981;50.00000;40.00000;1
 506.72800;31.36000;102.35981;50.00000;40.00000;1
 507.91400;31.44000;102.33645;50.00000;40.00000;1
 509.11700;31.52000;102.38318;50.00000;40.00000;1
 510.30701;31.60000;102.38318;50.00000;40.00000;1
 511.50601;31.68000;102.38318;50.00000;40.00000;1
 512.69598;31.76000;102.42991;50.00000;40.00000;1
 513.89899;31.84000;102.42991;50.00000;40.00000;1
 515.09003;31.92000;102.40654;50.00000;40.00000;1
 516.28998;32.00000;102.40654;50.00000;40.00000;1
 517.49200;32.08000;102.40654;50.00000;40.00000;1
 518.69000;32.16000;102.42991;50.00000;40.00000;1
 519.88898;32.24000;102.42991;50.00000;40.00000;1
 521.09003;32.32000;102.42991;50.00000;40.00000;1
 522.28900;32.40000;102.40654;50.00000;40.00000;1
 523.47803;32.48000;102.40654;50.00000;40.00000;1
 524.67902;32.56000;102.38318;50.00000;40.00000;1
 525.87701;32.64000;102.38318;50.00000;40.00000;1
 527.07703;32.72000;102.38318;50.00000;40.00000;1
 528.26898;32.80000;102.35981;50.00000;40.00000;1
 529.46002;32.88000;102.33645;50.00000;40.00000;1
 530.67297;32.96000;102.33645;50.00000;40.00000;1
 531.86200;33.04000;102.28972;50.00000;40.00000;1
 533.04901;33.12000;102.28972;50.00000;40.00000;1
 534.25098;33.20000;102.33645;50.00000;40.00000;1
 535.45203;33.28000;102.28972;50.00000;40.00000;1
 536.64001;33.36000;102.28972;50.00000;40.00000;1
 537.84698;33.44000;102.28972;50.00000;40.00000;1
 539.04199;33.52000;102.33645;50.00000;40.00000;1
 540.23297;33.60000;102.33645;50.00000;40.00000;1
 541.43903;33.68000;102.28972;50.00000;40.00000;1
 542.62701;33.76000;102.33645;50.00000;40.00000;1
 543.84302;33.84000;102.33645;50.00000;40.00000;1
 545.02899;33.92000;102.33645;50.00000;40.00000;1
 546.23297;34.00000;102.33645;50.00000;40.00000;1
 547.42499;34.08000;102.33645;50.00000;40.00000;1
 548.62000;34.16000;102.28972;50.00000;40.00000;1
 549.82098;34.24000;102.28972;50.00000;40.00000;1
 551.00897;34.32000;102.33645;50.00000;40.00000;1
 552.21802;34.40000;102.28972;50.00000;40.00000;1
 553.41400;34.48000;102.28972;50.00000;40.00000;1
 554.60303;34.56000;102.33645;50.00000;40.00000;1
 555.79498;34.64000;102.33645;50.00000;40.00000;1
 557.00201;34.72000;102.35981;50.00000;40.00000;1
 558.19299;34.80000;102.38318;50.00000;40.00000;1
 559.39203;34.88000;102.38318;50.00000;40.00000;1
 560.59802;34.96000;102.38318;50.00000;40.00000;1
 561.79401;35.04000;102.33645;50.00000;40.00000;1
 562.99402;35.12000;102.33645;50.00000;40.00000;1
 564.18701;35.20000;102.35981;50.00000;40.00000;1
 565.38898;35.28000;102.38318;50.00000;40.00000;1
 566.57703;35.36000;102.33645;50.00000;40.00000;1
 567.78400;35.44000;102.33645;50.00000;40.00000;1
 568.98102;35.52000;102.33645;50.00000;40.00000;1
 570.18701;35.60000;102.35981;50.00000;40.00000;1
 571.37000;35.68000;102.35981;50.00000;40.00000;1
 572.57397;35.76000;102.33645;50.00000;40.00000;1
 573.78302;35.84000;102.33645;50.00000;40.00000;1
 574.97302;35.92000;102.35981;50.00000;40.00000;1
 576.17798;36.00000;102.38318;50.00000;40.00000;1
 577.37299;36.08000;102.35981;50.00000;40.00000;1
 578.56598;36.16000;102.35981;50.00000;40.00000;1
 579.77002;36.24000;102.35981;50.00000;40.00000;1
 580.96100;36.32000;102.35981;50.00000;40.00000;1
 582.15900;36.40000;102.38318;50.00000;40.00000;1
 583.37201;36.48000;102.35981;50.00000;40.00000;1
 584.55902;36.56000;102.35981;50.00000;40.00000;1
 585.75598;36.64000;102.35981;50.00000;40.00000;1
 586.95697;36.72000;102.35981;50.00000;40.00000;1
 588.15198;36.80000;102.35981;50.00000;40.00000;1
 589.34900;36.88000;102.35981;50.00000;40.00000;1
 590.54700;36.96000;102.40654;50.00000;40.00000;1
 591.75201;37.04000;102.40654;50.00000;40.00000;1
 592.93903;37.12000;102.38318;50.00000;40.00000;1
 594.13501;37.20000;102.38318;50.00000;40.00000;1
 595.34198;37.28000;102.38318;50.00000;40.00000;1
 596.53003;37.36000;102.38318;50.00000;40.00000;1
 597.73401;37.44000;102.35981;50.00000;40.00000;1
 598.93298;37.52000;102.35981;50.00000;40.00000;1
 600.13599;37.60000;102.33645;50.00000;40.00000;1
 601.32397;37.68000;102.38318;50.00000;40.00000;1
 602.52600;37.76000;102.38318;50.00000;40.00000;1
 603.72400;37.84000;102.35981;50.00000;40.00000;1
 604.92700;37.92000;102.35981;50.00000;40.00000;1
 606.11700;38.00000;102.38318;50.00000;40.00000;1
 607.32001;38.08000;102.38318;50.00000;40.00000;1
 608.52301;38.16000;102.38318;50.00000;40.00000;1
 609.71600;38.24000;102.35981;50.00000;40.00000;1
 610.91400;38.32000;102.40654;50.00000;40.00000;1
 612.10999;38.40000;102.40654;50.00000;40.00000;1
 613.30798;38.48000;102.38318;50.00000;40.00000;1
 614.50403;38.56000;102.35981;50.00000;40.00000;1
 615.70099;38.64000;102.31308;50.00000;40.00000;1
 616.89301;38.72000;102.31308;50.00000;40.00000;1
 618.09698;38.80000;102.26636;50.00000;40.00000;1
 619.29401;38.88000;102.26636;50.00000;40.00000;1
 620.49597;38.96000;102.31308;50.00000;40.00000;1
 621.68799;39.04000;102.31308;50.00000;40.00000;1
 622.89099;39.12000;102.31308;50.00000;40.00000;1
 624.07397;39.20000;102.31308;50.00000;40.00000;1
 625.28101;39.28000;102.31308;50.00000;40.00000;1
 626.47601;39.36000;102.26636;50.00000;40.00000;1
 627.67102;39.44000;102.26636;50.00000;40.00000;1
 628.86499;39.52000;102.31308;50.00000;40.00000;1
 630.06598;39.60000;102.26636;50.00000;40.00000;1
 631.25702;39.68000;102.26636;50.00000;40.00000;1
 632.46002;39.76000;102.26636;50.00000;40.00000;1
 633.65302;39.84000;102.31308;50.00000;40.00000;1
 634.85797;39.92000;102.26635;50.00000;40.00000;1
 636.06403;40.00000;102.26635;50.00000;40.00000;1
 637.26202;40.08000;102.26635;50.00000;40.00000;1
 638.46198;40.16000;102.31308;50.00000;40.00000;1
 639.66400;40.24000;102.33645;50.00000;40.00000;1
 640.86798;40.32000;102.31308;50.00000;40.00000;1
 642.07300;40.40000;102.31308;50.00000;40.00000;1
 643.26599;40.48000;102.31308;50.00000;40.00000;1
 644.46301;40.56000;102.28972;50.00000;40.00000;1
 645.66498;40.64000;102.28972;50.00000;40.00000;1
 646.85999;40.72000;102.26636;50.00000;40.00000;1
 648.06403;40.80000;102.24299;50.00000;40.00000;1
 649.27301;40.88000;102.24299;50.00000;40.00000;1
 650.47302;40.96000;102.24299;50.00000;40.00000;1
 651.67798;41.04000;102.24299;50.00000;40.00000;1
 652.87201;41.12000;102.24299;50.00000;40.00000;1
 654.07202;41.20000;102.26635;50.00000;40.00000;1
 655.27899;41.28000;102.31308;50.00000;40.00000;1
 656.47998;41.36000;102.28972;50.00000;40.00000;1
 657.67700;41.44000;102.31308;50.00000;40.00000;1
 658.87799;41.52000;102.28972;50.00000;40.00000;1
 660.06897;41.60000;102.31308;50.00000;40.00000;1
 661.27600;41.68000;102.31308;50.00000;40.00000;1
 662.47699;41.76000;102.31308;50.00000;40.00000;1
 663.67297;41.84000;102.28972;50.00000;40.00000;1
 664.87201;41.92000;102.28972;50.00000;40.00000;1
 666.07599;42.00000;102.31308;50.00000;40.00000;1
 667.27100;42.08000;102.31308;50.00000;40.00000;1
 668.47101;42.16000;102.26636;50.00000;40.00000;1
 669.66803;42.24000;102.26636;50.00000;40.00000;1
 670.86798;42.32000;102.26636;50.00000;40.00000;1
 672.06598;42.40000;102.31308;50.00000;40.00000;1
 673.26801;42.48000;102.26635;50.00000;40.00000;1
 674.46002;42.56000;102.26635;50.00000;40.00000;1
 675.66803;42.64000;102.26635;50.00000;40.00000;1
 676.85797;42.72000;102.26635;50.00000;40.00000;1
 678.04901;42.80000;102.21963;50.00000;40.00000;1
 679.25201;42.88000;102.26636;50.00000;40.00000;1
 680.44897;42.96000;102.21963;50.00000;40.00000;1
 681.63800;43.04000;102.21963;50.00000;40.00000;1
 682.84198;43.12000;102.21963;50.00000;40.00000;1
 684.03699;43.20000;102.21963;50.00000;40.00000;1
 685.23499;43.28000;102.17290;50.00000;40.00000;1
 686.42499;43.36000;102.14953;50.00000;40.00000;1
 687.62402;43.44000;102.12617;50.00000;40.00000;1
 688.82800;43.52000;102.12617;50.00000;40.00000;1
 690.02899;43.60000;102.10280;50.00000;40.00000;1
 691.22302;43.68000;102.07944;50.00000;40.00000;1
 692.41998;43.76000;102.05608;50.00000;40.00000;1
 693.61102;43.84000;102.05607;50.00000;40.00000;1
 694.82501;43.92000;102.00935;50.00000;40.00000;1
 696.01398;44.00000;101.98598;50.00000;40.00000;1
 697.21503;44.08000;101.96262;50.00000;40.00000;1
 698.40802;44.16000;101.93925;50.00000;40.00000;1
 699.61798;44.24000;101.89252;50.00000;40.00000;1
 700.79999;44.32000;101.89252;50.00000;40.00000;1
 702.00800;44.40000;101.89252;50.00000;40.00000;1
 703.21198;44.48000;101.89252;50.00000;40.00000;1
 704.41199;44.56000;101.84579;50.00000;40.00000;1
 705.60498;44.64000;101.89252;50.00000;40.00000;1
 706.81097;44.72000;101.84579;50.00000;40.00000;1
 708.01099;44.80000;101.79907;50.00000;40.00000;1
 709.20801;44.88000;101.84579;50.00000;40.00000;1
 710.40900;44.96000;101.77570;50.00000;40.00000;1
 711.61102;45.04000;101.75234;50.00000;40.00000;1
 712.81500;45.12000;101.72897;50.00000;40.00000;1
 714.01300;45.20000;101.70561;50.00000;40.00000;1
 715.21100;45.28000;101.72897;50.00000;40.00000;1
 716.40601;45.36000;101.72897;50.00000;40.00000;1
 717.60602;45.44000;101.70561;50.00000;40.00000;1
 718.80798;45.52000;101.68224;50.00000;40.00000;1
 719.99701;45.60000;101.68224;50.00000;40.00000;1
 721.19800;45.68000;101.65888;50.00000;40.00000;1
 722.39697;45.76000;101.63551;50.00000;40.00000;1
 723.59601;45.84000;101.61215;50.00000;40.00000;1
 724.80103;45.92000;101.56542;50.00000;40.00000;1
 725.98901;46.00000;101.51869;50.00000;40.00000;1
 727.18597;46.08000;101.54206;50.00000;40.00000;1
 728.38702;46.16000;101.49533;50.00000;40.00000;1
 729.57599;46.24000;101.47196;50.00000;40.00000;1
 730.77399;46.32000;101.42523;50.00000;40.00000;1
 731.97803;46.40000;101.40187;50.00000;40.00000;1
 733.17798;46.48000;101.37850;50.00000;40.00000;1
 734.38300;46.56000;101.35514;50.00000;40.00000;1
 735.57397;46.64000;101.33178;50.00000;40.00000;1
 736.77301;46.72000;101.30841;50.00000;40.00000;1
 737.96997;46.80000;101.28505;50.00000;40.00000;1
 739.18597;46.88000;101.28505;50.00000;40.00000;1
 740.38599;46.96000;101.23832;50.00000;40.00000;1
 741.59399;47.04000;101.19159;50.00000;40.00000;1
 742.78900;47.12000;101.16822;50.00000;40.00000;1
 743.99402;47.20000;101.12150;50.00000;40.00000;1
 745.18402;47.28000;101.09813;50.00000;40.00000;1
 746.38202;47.36000;101.05140;50.00000;40.00000;1
 747.59601;47.44000;101.00467;50.00000;40.00000;1
 748.78900;47.52000;100.98131;50.00000;40.00000;1
 749.99902;47.60000;100.98131;50.00000;40.00000;1
 751.20203;47.68000;100.95794;50.00000;40.00000;1
 752.41101;47.76000;100.91121;50.00000;40.00000;1
 753.61902;47.84000;100.86449;50.00000;40.00000;1
 754.81097;47.92000;100.81776;50.00000;40.00000;1
 756.01801;48.00000;100.81776;50.00000;40.00000;1
 757.21802;48.08000;100.77103;50.00000;40.00000;1
 758.41699;48.16000;100.72430;50.00000;40.00000;1
 759.62097;48.24000;100.72430;50.00000;40.00000;1
 760.82703;48.32000;100.67757;50.00000;40.00000;1
 762.02600;48.40000;100.63084;50.00000;40.00000;1
 763.22900;48.48000;100.58411;50.00000;40.00000;1
 764.42902;48.56000;100.53738;50.00000;40.00000;1
 765.62701;48.64000;100.46729;50.00000;40.00000;1
 766.83002;48.72000;100.46729;50.00000;40.00000;1
 768.03198;48.80000;100.42056;50.00000;40.00000;1
 769.22101;48.88000;100.37383;50.00000;40.00000;1
 770.42401;48.96000;100.32710;50.00000;40.00000;1
 771.62799;49.04000;100.30374;50.00000;40.00000;1
 772.82300;49.12000;100.25701;50.00000;40.00000;1
 774.02301;49.20000;100.21028;50.00000;40.00000;1
 775.22400;49.28000;100.16355;50.00000;40.00000;1
 776.42700;49.36000;100.11682;50.00000;40.00000;1
 777.62598;49.44000;100.07009;50.00000;40.00000;1
 778.82300;49.52000;100.00000;50.00000;40.00000;1
 780.02502;49.60000; 99.95327;50.00000;40.00000;1
 781.21997;49.68000; 99.85981;50.00000;40.00000;1
 782.42102;49.76000; 99.78972;50.00000;40.00000;1
 783.61798;49.84000; 99.78972;50.00000;40.00000;1
 784.82300;49.92000; 99.74299;50.00000;40.00000;1
 786.01703;50.00000; 99.64953;50.00000;40.00000;1
 787.22998;50.08000; 99.60280;50.00000;40.00000;1
 788.42200;50.16000; 99.53271;50.00000;40.00000;1
 789.63098;50.24000; 99.53271;50.00000;40.00000;1
 790.83600;50.32000; 99.48598;50.00000;40.00000;1
 792.03601;50.40000; 99.43925;50.00000;40.00000;1
 793.23999;50.48000; 99.34579;50.00000;40.00000;1
 794.44397;50.56000; 99.32243;50.00000;40.00000;1
 795.64301;50.64000; 99.25234;50.00000;40.00000;1
 796.85400;50.72000; 99.20561;50.00000;40.00000;1
 798.04999;50.80000; 99.13551;50.00000;40.00000;1
 799.25299;50.88000; 99.06542;50.00000;40.00000;1
 800.46301;50.96000; 98.99533;50.00000;40.00000;1
 801.65698;51.04000; 98.97196;50.00000;40.00000;1
 802.86102;51.12000; 98.87850;50.00000;40.00000;1
 804.06598;51.20000; 98.85514;50.00000;40.00000;1
 805.26001;51.28000; 98.78505;50.00000;40.00000;1
 806.45300;51.36000; 98.71495;50.00000;40.00000;1
 807.65503;51.44000; 98.64486;50.00000;40.00000;1
 808.85901;51.52000; 98.57477;50.00000;40.00000;1
 810.05103;51.60000; 98.52804;50.00000;40.00000;1
 811.24799;51.68000; 98.45794;50.00000;40.00000;1
 812.46198;51.76000; 98.38785;50.00000;40.00000;1
 813.65601;51.84000; 98.31776;50.00000;40.00000;1
 814.85400;51.92000; 98.22430;50.00000;40.00000;1
 816.05798;52.00000; 98.17757;50.00000;40.00000;1
 817.25500;52.08000; 98.10748;50.00000;40.00000;1
 818.45801;52.16000; 98.08411;50.00000;40.00000;1
 819.66901;52.24000; 97.96729;50.00000;40.00000;1
 820.85999;52.32000; 97.94393;50.00000;40.00000;1
 822.05499;52.40000; 97.82710;50.00000;40.00000;1
 823.25201;52.48000; 97.75701;50.00000;40.00000;1
 824.44800;52.56000; 97.66355;50.00000;40.00000;1
 825.66498;52.64000; 97.54673;50.00000;40.00000;1
 826.86200;52.72000; 97.52336;50.00000;40.00000;1
 828.05902;52.80000; 97.42991;50.00000;40.00000;1
 829.26001;52.88000; 97.33645;50.00000;40.00000;1
 830.45801;52.96000; 97.26636;50.00000;40.00000;1
 831.65698;53.04000; 97.14953;50.00000;40.00000;1
 832.85400;53.12000; 97.05607;50.00000;40.00000;1
 834.06000;53.20000; 96.98598;50.00000;40.00000;1
 835.25598;53.28000; 96.89252;50.00000;40.00000;1
 836.46503;53.36000; 96.84579;50.00000;40.00000;1
 837.67102;53.44000; 96.79907;50.00000;40.00000;1
 838.86798;53.52000; 96.68224;50.00000;40.00000;1
 840.06500;53.60000; 96.61215;50.00000;40.00000;1
 841.27002;53.68000; 96.49533;50.00000;40.00000;1
 842.47699;53.76000; 96.42523;50.00000;40.00000;1
 843.67700;53.84000; 96.33178;50.00000;40.00000;1
 844.88098;53.92000; 96.21495;50.00000;40.00000;1
 846.09198;54.00000; 96.09813;50.00000;40.00000;1
 847.28699;54.08000; 96.00467;50.00000;40.00000;1
 848.48999;54.16000; 95.86449;50.00000;40.00000;1
 849.68701;54.24000; 95.77103;50.00000;40.00000;1
 850.89398;54.32000; 95.70093;50.00000;40.00000;1
 852.09802;54.40000; 95.56075;50.00000;40.00000;1
 853.30298;54.48000; 95.46729;50.00000;40.00000;1
 854.50403;54.56000; 95.37383;50.00000;40.00000;1
 855.71600;54.64000; 95.25701;50.00000;40.00000;1
 856.91498;54.72000; 95.14019;50.00000;40.00000;1
 858.12598;54.80000; 95.00000;50.00000;40.00000;1
 859.33002;54.88000; 94.88318;50.00000;40.00000;1
 860.53198;54.96000; 94.76636;50.00000;40.00000;1
 861.73499;55.04000; 94.60280;50.00000;40.00000;1
 862.94098;55.12000; 94.43925;50.00000;40.00000;1
 864.14502;55.20000; 94.32243;50.00000;40.00000;1
 865.34601;55.28000; 94.18224;50.00000;40.00000;1
 866.54999;55.36000; 94.04206;50.00000;40.00000;1
 867.75500;55.44000; 93.90187;50.00000;40.00000;1
 868.96698;55.52000; 93.76168;50.00000;40.00000;1
 870.16199;55.60000; 93.64486;50.00000;40.00000;1
 871.35901;55.68000; 93.50467;50.00000;40.00000;1
 872.57098;55.76000; 93.31776;50.00000;40.00000;1
 873.76703;55.84000; 93.15421;50.00000;40.00000;1
 874.96002;55.92000; 92.99065;50.00000;40.00000;1
 876.16199;56.00000; 92.80374;50.00000;40.00000;1
 877.36499;56.08000; 92.66355;50.00000;40.00000;1
 878.55701;56.16000; 92.52336;50.00000;40.00000;1
 879.76001;56.24000; 92.38318;50.00000;40.00000;1
 880.96301;56.32000; 92.19626;50.00000;40.00000;1
 882.16998;56.40000; 92.00935;50.00000;40.00000;1
 883.35901;56.48000; 91.84579;50.00000;40.00000;1
 884.55701;56.56000; 91.68224;50.00000;40.00000;1
 885.76599;56.64000; 91.54206;50.00000;40.00000;1
 886.96399;56.72000; 91.30841;50.00000;40.00000;1
 888.16498;56.80000; 91.12150;50.00000;40.00000;1
 889.37299;56.88000; 90.88785;50.00000;40.00000;1
 890.56799;56.96000; 90.63084;50.00000;40.00000;1
 891.76001;57.04000; 90.42056;50.00000;40.00000;1
 892.96600;57.12000; 90.21028;50.00000;40.00000;1
 894.17102;57.20000; 90.00000;50.00000;40.00000;1
 895.37201;57.28000; 89.71963;50.00000;40.00000;1
 896.56897;57.36000; 89.48598;50.00000;40.00000;1
 897.76801;57.44000; 89.22897;50.00000;40.00000;1
 898.97803;57.52000; 88.99533;50.00000;40.00000;1
 900.17297;57.60000; 88.73832;50.00000;40.00000;1
 901.37799;57.68000; 88.50467;50.00000;40.00000;1
 902.57599;57.76000; 88.20093;50.00000;40.00000;1
 903.78198;57.84000; 87.89720;50.00000;40.00000;1
 904.98199;57.92000; 87.59346;50.00000;40.00000;1
 906.19202;58.00000; 87.33645;50.00000;40.00000;1
 907.41101;58.08000; 87.05607;50.00000;40.00000;1
 908.60901;58.16000; 86.72897;50.00000;40.00000;1
 909.82202;58.24000; 86.40187;50.00000;40.00000;1
 911.02600;58.32000; 86.07477;50.00000;40.00000;1
 912.23700;58.40000; 85.79439;50.00000;40.00000;1
 913.44800;58.48000; 85.44393;50.00000;40.00000;1
 914.65002;58.56000; 85.11682;50.00000;40.00000;1
 915.85797;58.64000; 84.76636;50.00000;40.00000;1
 917.07300;58.72000; 84.48598;50.00000;40.00000;1
 918.27399;58.80000; 84.08879;50.00000;40.00000;1
 919.48602;58.88000; 83.73832;50.00000;40.00000;1
 920.70099;58.96000; 83.36449;50.00000;40.00000;1
 921.90698;59.04000; 82.99065;50.00000;40.00000;1
 923.11499;59.12000; 82.61682;50.00000;40.00000;1
 924.33002;59.20000; 82.24299;50.00000;40.00000;1
 925.53699;59.28000; 81.82243;50.00000;40.00000;1
 926.73700;59.36000; 81.40187;50.00000;40.00000;1
 927.94098;59.44000; 80.95794;50.00000;40.00000;1
 929.15100;59.52000; 80.56075;50.00000;40.00000;1
 930.36401;59.60000; 80.09346;50.00000;40.00000;1
 931.56097;59.68000; 79.67290;50.00000;40.00000;1
 932.76099;59.76000; 79.22897;50.00000;40.00000;1
 933.97803;59.84000; 78.78505;50.00000;40.00000;1
 935.17798;59.92000; 78.24766;50.00000;40.00000;1
 936.38599;60.00000; 77.64019;50.00000;40.00000;1
 937.58600;60.08000; 77.10280;50.00000;40.00000;1
 938.78497;60.16000; 76.61215;50.00000;40.00000;1
 939.98999;60.24000; 76.16822;50.00000;40.00000;1
 941.19299;60.32000; 75.70094;50.00000;40.00000;1
 942.40002;60.40000; 75.21028;50.00000;40.00000;1
 943.60999;60.48000; 74.55608;50.00000;40.00000;1
 944.79999;60.56000; 73.97196;50.00000;40.00000;1
 945.98999;60.64000; 73.48131;50.00000;40.00000;1
 947.18903;60.72000; 72.99066;50.00000;40.00000;1
 948.39801;60.80000; 72.28972;50.00000;40.00000;1
 949.58801;60.88000; 71.65888;50.00000;40.00000;1
 950.79498;60.96000; 71.12149;50.00000;40.00000;1
 951.99701;61.04000; 70.65421;50.00000;40.00000;1
 953.19299;61.12000; 69.95327;50.00000;40.00000;1
 954.39600;61.20000; 69.32243;50.00000;40.00000;1
 955.58099;61.28000; 68.76168;50.00000;40.00000;1
 956.78101;61.36000; 68.03738;50.00000;40.00000;1
 957.98401;61.44000; 67.42991;50.00000;40.00000;1
 959.18103;61.52000; 66.75234;50.00000;40.00000;1
 960.38000;61.60000; 66.14486;50.00000;40.00000;1
 961.58398;61.68000; 65.53738;50.00000;40.00000;1
 962.78998;61.76000; 64.85981;50.00000;40.00000;1
 963.98901;61.84000; 64.18224;50.00000;40.00000;1
 965.19098;61.92000; 63.50467;50.00000;40.00000;1
 966.39600;62.00000; 62.87383;50.00000;40.00000;1
 967.59998;62.08000; 62.19626;50.00000;40.00000;1
 968.80603;62.16000; 61.51869;50.00000;40.00000;1
 970.00897;62.24000; 60.74766;50.00000;40.00000;1
 971.20599;62.32000; 60.04673;50.00000;40.00000;1
 972.40900;62.40000; 59.36916;50.00000;40.00000;1
 973.61298;62.48000; 58.64486;50.00000;40.00000;1
 974.81000;62.56000; 57.92056;50.00000;40.00000;1
 976.01501;62.64000; 57.21963;50.00000;40.00000;1
 977.21198;62.72000; 56.49533;50.00000;40.00000;1
 978.41498;62.80000; 55.74766;50.00000;40.00000;1
 979.61798;62.88000; 54.97664;50.00000;40.00000;1
 980.81000;62.96000; 54.25234;50.00000;40.00000;1
 982.00201;63.04000; 53.50467;50.00000;40.00000;1
 983.19702;63.12000; 52.73364;50.00000;40.00000;1
 984.39001;63.20000; 51.96262;50.00000;40.00000;1
 985.59698;63.28000; 51.16822;50.00000;40.00000;1
 986.79401;63.36000; 50.37383;50.00000;40.00000;1
 987.99200;63.44000; 49.57944;50.00000;40.00000;1
 989.18799;63.52000; 48.76168;50.00000;40.00000;1
 990.39301;63.60000; 47.94393;50.00000;40.00000;1
 991.59302;63.68000; 47.14953;50.00000;40.00000;1
 992.78198;63.76000; 46.37850;50.00000;40.00000;1
 993.98102;63.84000; 45.56075;50.00000;40.00000;1
 995.17603;63.92000; 44.81308;50.00000;40.00000;1
 996.38098;64.00000; 44.06542;50.00000;40.00000;1
 997.58801;64.08000; 43.24766;50.00000;40.00000;1
 998.77399;64.16000; 42.45327;50.00000;40.00000;1
1002.03101;64.39750; 40.04673;50.00000;40.00000;2
1005.57098;64.79750; 36.02804;50.00000;40.00000;2
1006.35699;65.19750; 32.31308;50.00000;40.00000;2
1005.11200;65.59750; 28.69159;50.00000;40.00000;2
1003.01599;65.99750; 25.28037;50.00000;40.00000;2
1001.09399;66.39750; 22.10280;50.00000;40.00000;2
 999.83801;66.79750; 19.20560;50.00000;40.00000;2
 999.31598;67.19750; 16.26168;50.00000;40.00000;2
 999.32202;67.59750; 13.64486;50.00000;40.00000;2
 999.58600;67.99750; 11.56542;50.00000;40.00000;2
 999.88501;68.39750;  9.36916;50.00000;40.00000;2
1000.06897;68.79750;  7.40654;50.00000;40.00000;2
1000.12701;69.19750;  5.79439;50.00000;40.00000;2
1000.07501;69.59750;  4.43925;50.00000;40.00000;2
 999.96600;69.99750;  3.36449;50.00000;40.00000;2
 999.87402;70.39750;  2.68692;50.00000;40.00000;2
 999.80103;70.79750;  2.21962;50.00000;40.00000;2
 999.79303;71.19750;  1.96262;50.00000;40.00000;2
 999.82703;71.59750;  1.86916;50.00000;40.00000;2
 999.89398;71.99750;  1.82243;50.00000;40.00000;2
 999.94800;72.39750;  1.89252;50.00000;40.00000;2
 999.98199;72.79750;  1.89253;50.00000;40.00000;2
 999.99799;73.19750;  1.86915;50.00000;40.00000;2
1000.00201;73.59750;  1.91589;50.00000;40.00000;2
1000.00897;73.99750;  1.91588;50.00000;40.00000;2
1000.00800;74.39750;  1.96262;50.00000;40.00000;2
1000.00702;74.79750;  1.98599;50.00000;40.00000;2
1000.00000;75.19750;  1.96262;50.00000;40.00000;2
 999.99103;75.59750;  1.91588;50.00000;40.00000;2
 999.98999;75.99750;  1.84580;50.00000;40.00000;2
1000.00098;76.39750;  1.91589;50.00000;40.00000;2
 999.99799;76.79750;  1.86916;50.00000;40.00000;2
1000.01300;77.19750;  1.84579;50.00000;40.00000;2
1000.01398;77.59750;  1.84580;50.00000;40.00000;2
1000.02399;77.99750;  1.84579;50.00000;40.00000;2
1000.02002;78.39750;  1.84580;50.00000;40.00000;2
1000.02197;78.79750;  1.86916;50.00000;40.00000;2
1000.02301;79.19750;  1.84580;50.00000;40.00000;2
1000.01099;79.59750;  1.91589;50.00000;40.00000;2
1000.01099;79.99750;  1.91589;50.00000;40.00000;2
1000.01398;80.39750;  1.96261;50.00000;40.00000;2
1000.02399;80.79750;  1.91589;50.00000;40.00000;2
1000.03497;81.19750;  1.96262;50.00000;40.00000;2
1000.02698;81.59750;  1.98598;50.00000;40.00000;2
1000.02502;81.99750;  1.93925;50.00000;40.00000;2
1000.02002;82.39750;  1.93925;50.00000;40.00000;2
1000.01703;82.79750;  1.93926;50.00000;40.00000;2
1000.02197;83.19750;  1.93925;50.00000;40.00000;2
1000.00500;83.59750;  1.93926;50.00000;40.00000;2
1000.01202;83.99750;  1.93925;50.00000;40.00000;2
1000.01202;84.39750;  1.93925;50.00000;40.00000;2
1000.01703;84.79750;  2.00935;50.00000;40.00000;2
1000.02502;85.19750;  1.98598;50.00000;40.00000;2
1000.02502;85.59750;  2.05608;50.00000;40.00000;2
1000.02002;85.99750;  2.00934;50.00000;40.00000;2
1000.01398;86.39750;  2.00935;50.00000;40.00000;2
1000.01898;86.79750;  2.05608;50.00000;40.00000;2
1000.02899;87.19750;  2.07944;50.00000;40.00000;2
1000.02600;87.59750;  2.03271;50.00000;40.00000;2
1000.03003;87.99750;  1.96261;50.00000;40.00000;2
1000.02600;88.39750;  1.96262;50.00000;40.00000;2
1000.03003;88.79750;  2.00935;50.00000;40.00000;2
1000.02197;89.19750;  1.91588;50.00000;40.00000;2
1000.01599;89.59750;  1.96261;50.00000;40.00000;2
1000.01801;89.99750;  2.00934;50.00000;40.00000;2
1000.01801;90.39750;  2.05607;50.00000;40.00000;2
1000.01703;90.79750;  2.03271;50.00000;40.00000;2
1000.01898;91.19750;  2.00935;50.00000;40.00000;2
1000.01300;91.59750;  2.00934;50.00000;40.00000;2
1000.01300;91.99750;  1.96261;50.00000;40.00000;2
1000.00702;92.39750;  1.96262;50.00000;40.00000;2
1000.01801;92.79750;  2.00935;50.00000;40.00000;2
1000.02002;93.19750;  2.05608;50.00000;40.00000;2
1000.01599;93.59750;  2.00934;50.00000;40.00000;2
1000.02399;93.99750;  1.98598;50.00000;40.00000;2
1000.02002;94.20083;  2.03271;50.00000;40.00000;2